Workbook

Sheet Raw Data
A1: idstd | B1: a2 | C1: a6a | D1: a6c | E1: d1a2_v4 | F1: b5 | G1: b7 | H1: wmedian | I1: d2 | J1: n3 | K1: f1 | L1: l1 | M1: l2 | N1: n2a | O1: n2e | P1: n7a | Q1: d3c | R1: r2 | S1: h1 | T1: h5 | U1: k3a | V1: k3bc | W1: k3f | X1: k4 | Y1: n5a | Z1: k82a | AA1: k162a | AB1: c6 | AC1: c7 | AD1: c30a | AE1: k30 | AF1: l30b | AG1: e30 | AH1: m1a | AI1: a17
A2: 1614120 | B2: 3 | C2: 3 | D2: 1000 | E2: 1073 | F2: 1986 | G2: 24 | H2: 1 | I2: 1200000000 | J2: 900000000 | K2: 20 | L2: 250 | M2: 180 | N2: 500000000 | O2: 200000000 | P2: 350000000 | Q2: 25 | R2: 1 | S2: 2 | T2: 2 | U2: 85 | V2: 0 | W2: 0 | X2: 2 | Z2: 2 | AA2: 2 | AB2: 1 | AC2: 6 | AD2: 2 | AE2: 3 | AF2: 2 | AG2: 2 | AH2: 14 | AI2: 4
A3: 1614122 | B3: 3 | C3: 1 | D3: 10 | E3: 1410 | F3: 1970 | G3: 30 | H3: 55.69917 | I3: 45000000 | J3: 40000000 | K3: 70 | L3: 6 | M3: 5 | N3: 7200000 | O3: 6000000 | P3: 30000000 | Q3: 0 | S3: 2 | T3: 2 | U3: 100 | V3: 0 | W3: 0 | X3: 2 | Z3: 2 | AA3: 2 | AB3: 1 | AC3: 2 | AD3: 4 | AE3: 2 | AF3: 0 | AG3: 0 | AH3: 8 | AI3: 1
A4: 1614124 | B4: 1 | C4: 2 | D4: 100 | E4: 1073 | F4: 2007 | G4: 20 | H4: 24.842424 | I4: 3000000000 | J4: 2000000000 | K4: 70 | L4: 50 | M4: 50 | N4: 700000000 | O4: 400000000 | P4: 5000000000 | Q4: 0 | R4: 1 | S4: 2 | T4: 2 | U4: 80 | V4: 0 | W4: 0 | X4: 2 | Z4: 2 | AA4: 2 | AB4: 2 | AD4: 2 | AE4: 1 | AF4: 1 | AG4: 2 | AH4: 4 | AI4: 1
A5: 1614125 | B5: 1 | C5: 3 | D5: 110 | E5: 2100 | F5: 1981 | G5: 44 | H5: 1 | I5: 13000000000 | J5: 13000000000 | K5: 90 | L5: 57 | M5: 44 | N5: 1500000000 | O5: 6000000000 | P5: 12000000000 | Q5: 1 | R5: 1 | S5: 2 | T5: 2 | U5: 100 | V5: 0 | W5: 0 | X5: 1 | Y5: 600000000 | Z5: 1 | AA5: 2 | AB5: 1 | AC5: 10 | AD5: 3 | AE5: 1 | AF5: 3 | AG5: 3 | AH5: 1 | AI5: 1
A6: 1614130 | B6: 1 | C6: 1 | D6: 7 | E6: 3100 | F6: 2020 | G6: 15 | H6: 143.61815 | I6: 24000000 | J6: 17000000 | K6: 70 | L6: 5 | M6: 4 | N6: 4100000 | O6: 12000000 | P6: 11000000 | Q6: 0 | S6: 1 | T6: 1 | U6: 60 | V6: 10 | W6: 30 | X6: 1 | Y6: 500000 | Z6: 1 | AA6: 2 | AB6: 1 | AC6: 6 | AD6: 1 | AE6: 0 | AF6: 0 | AG6: 1 | AH6: 14 | AI6: 4
A7: 1614131 | B7: 1 | C7: 1 | D7: 16 | E7: 1811 | F7: 1985 | G7: 30 | H7: 157.86736 | I7: 100000000 | J7: 80000000 | K7: 20 | L7: 16 | M7: 16 | N7: 5000000 | O7: 20000000 | P7: 350000000 | Q7: 0 | S7: 2 | T7: 2 | U7: 80 | V7: 0 | W7: 0 | X7: 2 | Z7: 2 | AA7: 2 | AB7: 2 | AD7: 1 | AE7: 0 | AF7: 0 | AG7: 0 | AH7: 8 | AI7: 4
A8: 1614136 | B8: 1 | C8: 3 | D8: 1850 | E8: 2410 | F8: 1983 | G8: 42 | H8: 1 | I8: 6000000000000 | J8: 4000000000000 | K8: 92 | L8: 2000 | M8: 1800 | N8: 1000000000000 | O8: 3000000000000 | P8: 1000000000000 | Q8: 35 | R8: 1 | S8: 1 | T8: 1 | U8: 35 | V8: 30 | W8: 25 | X8: 1 | Y8: 1000000000000 | Z8: 1 | AA8: 1 | AB8: 1 | AC8: 2 | AD8: 2 | AE8: 2 | AF8: 1 | AG8: 2 | AH8: 14 | AI8: 1
A9: 1614138 | B9: 3 | C9: 1 | D9: 9 | E9: 1079 | F9: 1992 | G9: 30 | H9: 1.7886078 | I9: 38000000 | J9: 6000000 | K9: 100 | L9: 9 | M9: 9 | N9: 10000000 | O9: -9 | P9: 15000000 | Q9: 0 | S9: 2 | T9: 2 | U9: 40 | V9: 0 | W9: 0 | X9: 2 | Z9: 2 | AA9: 2 | AB9: 1 | AC9: 8 | AD9: 4 | AE9: 2 | AF9: 0 | AG9: 4 | AH9: 1 | AI9: 4
A10: 1614139 | B10: 2 | C10: 1 | D10: 5 | E10: 3100 | F10: 2002 | G10: 24 | H10: 68.62606 | I10: 40000000 | J10: 22000000 | K10: 4 | L10: 5 | M10: 5 | N10: 12000000 | O10: 16000000 | P10: 24200000 | Q10: 0 | S10: 2 | T10: 2 | U10: 20 | V10: 60 | W10: 0 | X10: 1 | Y10: 1000000 | Z10: 1 | AA10: 2 | AB10: 1 | AC10: 5 | AD10: 3 | AE10: 4 | AF10: 0 | AG10: 1 | AH10: 1 | AI10: 2
A11: 1614143 | B11: 1 | C11: 1 | D11: 6 | E11: 2599 | F11: 1987 | G11: 35 | H11: 157.86736 | I11: 10000000 | J11: 10000000 | K11: 100 | L11: 6 | M11: 6 | N11: 6000000 | O11: 3000000 | P11: 7000000 | Q11: 0 | S11: 2 | T11: 2 | U11: 80 | V11: 10 | W11: 0 | X11: 2 | Z11: 2 | AA11: 1 | AB11: 1 | AC11: 2 | AD11: 1 | AE11: 3 | AF11: 0 | AG11: 1 | AH11: 1 | AI11: 4
A12: 1614144 | B12: 1 | C12: 1 | D12: 50 | E12: 1812 | F12: 1995 | G12: 17 | H12: 585.9553 | I12: 300000000 | J12: 110000000 | K12: 95 | L12: 40 | M12: 20 | N12: 30000000 | O12: 40000000 | P12: 1000000000 | Q12: 10 | R12: 1 | S12: 2 | T12: 1 | U12: 80 | V12: 10 | W12: 0 | X12: 1 | Y12: 300000000 | Z12: 1 | AA12: 2 | AB12: 1 | AC12: 6 | AD12: 1 | AE12: 0 | AF12: 0 | AG12: 1 | AH12: 7 | AI12: 2
A13: 1614146 | B13: 1 | C13: 1 | D13: 80 | E13: 2023 | F13: 2005 | G13: 20 | H13: 585.9553 | I13: 2000000000 | J13: 1000000000 | K13: 70 | L13: 80 | M13: 40 | N13: 200000000 | O13: 800000000 | P13: 700000000 | Q13: 30 | R13: 1 | S13: 1 | T13: 1 | U13: 40 | V13: 5 | W13: 0 | X13: 1 | Y13: 80000000 | Z13: 1 | AA13: 2 | AB13: 1 | AC13: 4 | AD13: 3 | AE13: 0 | AF13: 0 | AG13: 0 | AH13: 14 | AI13: 4
A14: 1614147 | B14: 3 | C14: 3 | D14: 100 | E14: 1079 | F14: 1982 | G14: 43 | H14: 1 | I14: 3000000000 | J14: 2500000000 | K14: 30 | L14: 35 | M14: 35 | N14: 300000000 | O14: 900000000 | P14: 600000000 | Q14: 10 | R14: 1 | S14: 2 | T14: 1 | U14: 100 | V14: 0 | W14: 0 | X14: 2 | Z14: 2 | AA14: 2 | AB14: 1 | AC14: 5 | AD14: 3 | AE14: 1 | AF14: 2 | AG14: 4 | AH14: 12 | AI14: 4
A15: 1614149 | B15: 4 | C15: 2 | D15: 10 | E15: 1040 | F15: 2013 | G15: 10 | H15: 1.826539 | I15: 300000000 | J15: 250000000 | K15: 100 | L15: 15 | M15: 10 | N15: 70000000 | O15: 100000000 | P15: 400000000 | Q15: 0 | S15: 2 | T15: 2 | U15: 40 | V15: 0 | W15: 40 | X15: 2 | Z15: 2 | AA15: 2 | AB15: 1 | AC15: 7 | AD15: 2 | AE15: 1 | AF15: 0 | AG15: 4 | AH15: 12 | AI15: 4
A16: 1614151 | B16: 1 | C16: 3 | D16: 355 | E16: 1079 | F16: 1994 | G16: 25 | H16: 1 | I16: 68000000000 | J16: 67000000000 | K16: 69 | L16: 124 | M16: 118 | N16: 4140000000 | O16: 37820000000 | P16: 95000000000 | Q16: 1 | R16: 1 | S16: 1 | T16: 2 | U16: 100 | V16: 0 | W16: 0 | X16: 2 | Z16: 2 | AA16: 2 | AB16: 1 | AC16: 10 | AD16: 4 | AE16: 1 | AF16: 1 | AG16: 4 | AH16: 8 | AI16: 4
A17: 1614153 | B17: 3 | C17: 2 | D17: 8 | E17: 3100 | F17: 2021 | G17: 5 | H17: 3.0692382 | I17: 60000000 | J17: 30000000 | K17: 70 | L17: 8 | M17: 8 | N17: 20000000 | O17: 35000000 | P17: -9 | Q17: 0 | S17: 2 | T17: 2 | U17: 30 | V17: 25 | W17: 20 | X17: 2 | Z17: 1 | AA17: 2 | AB17: 1 | AC17: 6 | AD17: 1 | AE17: 3 | AF17: 0 | AG17: 3 | AH17: 14 | AI17: 1
A18: 1614155 | B18: 2 | C18: 2 | D18: 16 | E18: 1410 | F18: 1990 | G18: 35 | H18: 2.4641058 | I18: 57242000 | J18: 35000000 | K18: 13 | L18: 6 | M18: 6 | N18: 18000000 | O18: 22500000 | P18: 26500000 | Q18: 0 | S18: 2 | T18: 2 | U18: 50 | V18: 10 | W18: 10 | X18: 2 | Z18: 1 | AA18: 1 | AB18: 1 | AC18: 0 | AD18: 1 | AE18: 3 | AF18: 0 | AG18: 1 | AH18: 1 | AI18: 4
A19: 1614157 | B19: 3 | C19: 1 | D19: 7 | E19: 1061 | F19: 2015 | G19: 10 | H19: 26.253841 | I19: 32000000 | J19: 28000000 | K19: 65 | L19: 7 | M19: 7 | N19: 12000000 | O19: 18000000 | P19: 20000000 | Q19: 0 | S19: 2 | T19: 2 | U19: 80 | V19: 0 | W19: 0 | X19: 2 | Z19: 2 | AA19: 2 | AB19: 1 | AC19: 8 | AD19: 2 | AE19: 3 | AF19: 0 | AG19: 3 | AH19: 14 | AI19: 2
A20: 1614160 | B20: 2 | C20: 1 | D20: 16 | E20: 3100 | F20: 2009 | G20: 20 | H20: 68.62606 | I20: 45000000 | J20: 18000000 | K20: 60 | L20: 12 | M20: 8 | N20: -9 | O20: 30000000 | P20: 50000000 | Q20: 0 | S20: 2 | T20: 1 | U20: 50 | V20: 25 | W20: 0 | X20: 2 | Z20: 1 | AA20: 1 | AB20: 1 | AC20: 30 | AD20: 3 | AE20: 2 | AF20: 1 | AG20: 3 | AH20: 8 | AI20: 2
A21: 1614161 | B21: 3 | C21: 1 | D21: 7 | E21: 1061 | F21: 2000 | G21: 25 | H21: 118.82497 | I21: 154000000 | J21: 144000000 | K21: 100 | L21: 7 | M21: 7 | N21: 21600000 | O21: 35000000 | P21: 300000000 | Q21: 0 | S21: 2 | T21: 2 | U21: 70 | V21: 0 | W21: 0 | X21: 2 | Z21: 2 | AA21: 2 | AB21: 1 | AC21: 1 | AD21: 2 | AE21: 4 | AF21: 0 | AG21: 3 | AH21: 8 | AI21: 1
A22: 1614163 | B22: 4 | C22: 1 | D22: 30 | E22: 1040 | F22: 1994 | G22: 4 | H22: 1 | I22: 2165000000 | J22: 1800000000 | K22: 100 | L22: 15 | M22: 10 | N22: 720000000 | O22: 900000000 | P22: 10000000000 | Q22: 0 | R22: 1 | S22: 1 | T22: 2 | U22: 0 | V22: 0 | W22: 30 | X22: 1 | Y22: 100000000 | Z22: 2 | AA22: 2 | AB22: 1 | AC22: 3 | AD22: 1 | AE22: 0 | AF22: 0 | AG22: 3 | AH22: 2 | AI22: 1
A23: 1614165 | B23: 3 | C23: 2 | D23: 13 | E23: 1061 | F23: 2006 | G23: 22 | H23: 2.7846396 | I23: 600000000 | J23: 400000000 | K23: 90 | L23: 7 | M23: 8 | N23: 62400000 | O23: 40000000 | P23: 90000000 | Q23: 0 | S23: 1 | T23: 2 | U23: 100 | V23: 0 | W23: 0 | X23: 2 | Z23: 2 | AA23: 1 | AB23: 1 | AC23: 3 | AD23: 3 | AE23: 3 | AF23: 1 | AG23: 2 | AH23: 12 | AI23: 1
A24: 1614170 | B24: 1 | C24: 1 | D24: 15 | E24: 2511 | F24: 2009 | G24: 22 | H24: 316.3196 | I24: 800000000 | J24: 500000000 | K24: 90 | L24: 15 | M24: 7 | N24: 25000000 | O24: -9 | P24: -9 | Q24: 20 | S24: 1 | T24: 2 | U24: 60 | V24: 20 | W24: 0 | X24: 2 | Z24: 1 | AA24: 2 | AB24: 1 | AC24: 8 | AD24: 1 | AE24: 0 | AF24: 0 | AG24: 0 | AH24: 4 | AI24: 4
A25: 1614171 | B25: 3 | C25: 1 | D25: 10 | E25: 2511 | F25: 2007 | G25: 20 | H25: 90.16523 | I25: 70000000 | J25: 10000000 | K25: 70 | L25: 10 | M25: 3 | N25: 10000000 | O25: 30000000 | P25: 170000000 | Q25: 0 | S25: 2 | T25: 2 | U25: 90 | V25: 0 | W25: 0 | X25: 2 | Z25: 2 | AA25: 2 | AB25: 1 | AC25: 3 | AD25: 2 | AE25: 0 | AF25: 0 | AG25: 0 | AH25: 8 | AI25: 1
A26: 1614174 | B26: 4 | C26: 1 | D26: 6 | E26: 1811 | F26: 1997 | G26: 30 | H26: 18.668732 | I26: 15000000 | J26: 12000000 | K26: 100 | L26: 6 | M26: 6 | N26: 4000000 | O26: 5000000 | P26: 100000000 | Q26: 0 | S26: 2 | T26: 2 | U26: 50 | V26: 50 | W26: 0 | X26: 2 | Z26: 2 | AA26: 2 | AB26: 1 | AC26: 5 | AD26: 3 | AE26: 1 | AF26: 1 | AG26: 1 | AH26: 3 | AI26: 4
A27: 1614175 | B27: 4 | C27: 1 | D27: 8 | E27: 1811 | F27: 2006 | G27: 19 | H27: 18.668732 | I27: 29430000 | J27: 22570000 | K27: 70 | L27: 4 | M27: 4 | N27: 8046000 | O27: 17000000 | P27: 49570000 | Q27: 0 | S27: 2 | T27: 2 | U27: 60 | V27: 0 | W27: 10 | X27: 1 | Y27: 2460000 | Z27: 2 | AA27: 2 | AB27: 1 | AC27: 6 | AD27: 2 | AE27: 1 | AF27: 0 | AG27: 0 | AH27: 14 | AI27: 2
A28: 1614176 | B28: 1 | C28: 3 | D28: 100 | E28: 3100 | F28: 1987 | G28: 30 | H28: 2.6891484 | I28: 15000000000 | J28: 10000000000 | K28: 40 | L28: 40 | M28: 35 | N28: 2000000000 | O28: 500000000 | P28: 4000000000 | Q28: 0 | R28: 2 | S28: 2 | T28: 2 | U28: 100 | V28: 0 | W28: 0 | X28: 2 | Z28: 2 | AA28: 2 | AB28: 2 | AD28: 0 | AE28: 1 | AF28: 0 | AG28: 2 | AH28: 12 | AI28: 4
A29: 1614178 | B29: 1 | C29: 3 | D29: 10 | E29: 2599 | F29: 1984 | G29: 41 | H29: 1 | I29: 30000000 | J29: 40000000 | K29: 85 | L29: 7 | M29: 10 | N29: 4000000 | O29: 13000000 | P29: 35000000 | Q29: 0 | S29: 1 | T29: 2 | U29: 70 | V29: 30 | W29: 0 | X29: 2 | Z29: 1 | AA29: 2 | AB29: 1 | AC29: 3 | AD29: 1 | AE29: 1 | AF29: 1 | AG29: 2 | AH29: 14 | AI29: 1
A30: 1614179 | B30: 1 | C30: 3 | D30: 94 | E30: 2395 | F30: 2004 | G30: 20 | H30: 1.5225753 | I30: 2000000000 | J30: 1600000000 | K30: 76 | L30: 92 | M30: 76 | N30: -9 | O30: 500000000 | P30: 1800000000 | Q30: 0 | R30: 1 | S30: 1 | T30: 1 | U30: 100 | V30: 0 | W30: 0 | X30: 1 | Y30: 1800000000 | Z30: 2 | AA30: 2 | AB30: 1 | AC30: 10 | AD30: 3 | AE30: 1 | AF30: 0 | AG30: 2 | AH30: 8 | AI30: 1
A31: 1614180 | B31: 2 | C31: 2 | D31: 30 | E31: 1071 | F31: 2000 | G31: 30 | H31: 1.9028108 | I31: 800000000 | J31: 760000000 | K31: 10 | L31: 25 | M31: 27 | N31: 30000000 | O31: 450000000 | P31: 400000000 | Q31: 0 | R31: 1 | S31: 1 | T31: 1 | U31: 70 | V31: 0 | W31: 30 | X31: 1 | Y31: 200000000 | Z31: 2 | AA31: 2 | AB31: 1 | AC31: 0 | AD31: 2 | AE31: 2 | AF31: 3 | AG31: 2 | AH31: 4 | AI31: 2
A32: 1614182 | B32: 1 | C32: 1 | D32: 15 | E32: 2819 | F32: 2001 | G32: 15 | H32: 143.61815 | I32: -9 | J32: -9 | K32: 60 | L32: 20 | M32: 15 | N32: -9 | O32: -9 | P32: -9 | Q32: 0 | S32: 2 | T32: 2 | U32: 100 | V32: 0 | W32: 0 | X32: 1 | Y32: 0 | Z32: 2 | AA32: 2 | AB32: 1 | AC32: 8 | AD32: 4 | AE32: 4 | AF32: 0 | AG32: 4 | AH32: 1 | AI32: 3
A33: 1614183 | B33: 2 | C33: 2 | D33: 12 | E33: 1071 | F33: 2015 | G33: 10 | H33: 1.5243006 | I33: 217920000 | J33: -9 | K33: 2 | L33: 12 | M33: 24 | N33: 36950400 | O33: 172800000 | P33: 6000000 | Q33: 0 | S33: 1 | T33: 1 | U33: 80 | V33: 0 | W33: 20 | X33: 2 | Z33: 2 | AA33: 2 | AB33: 1 | AC33: 4 | AD33: 1 | AE33: 4 | AF33: 0 | AG33: 0 | AH33: 1 | AI33: 2
A34: 1614185 | B34: 1 | C34: 1 | D34: 7 | E34: 1811 | F34: 2000 | G34: 14 | H34: 157.86736 | I34: 30000000 | J34: 20000000 | K34: 90 | L34: 8 | M34: 2 | N34: 10000000 | O34: 15000000 | P34: 40000000 | Q34: 0 | S34: 2 | T34: 2 | U34: 20 | V34: 0 | W34: 70 | X34: 2 | Z34: 2 | AA34: 2 | AB34: 2 | AD34: 1 | AE34: 1 | AF34: 1 | AG34: 0 | AH34: 14 | AI34: 4
A35: 1614193 | B35: 3 | C35: 3 | D35: 300 | E35: 1061 | F35: 2009 | G35: 30 | H35: 1 | I35: 1200000000 | J35: 1000000000 | K35: 60 | L35: 300 | M35: 250 | N35: 200000000 | O35: 500000000 | P35: 600000000 | Q35: 30 | R35: 1 | S35: 2 | T35: 1 | U35: 60 | V35: 40 | W35: 0 | X35: 2 | Z35: 2 | AA35: 2 | AB35: 1 | AC35: 2 | AD35: 2 | AE35: 2 | AF35: 1 | AG35: 1 | AH35: 14 | AI35: 4
A36: 1614202 | B36: 2 | C36: 1 | D36: 5 | E36: 2511 | F36: 1996 | G36: 40 | H36: 68.62606 | I36: 12000000 | J36: -9 | K36: -9 | L36: 5 | M36: 6 | N36: -9 | O36: -9 | P36: 2500000 | Q36: 0 | S36: 1 | T36: 2 | U36: 20 | V36: 0 | W36: 80 | X36: 2 | Z36: 2 | AA36: 2 | AB36: -9 | AD36: 3 | AE36: 2 | AF36: 1 | AG36: 3 | AH36: 6 | AI36: 2
A37: 1614203 | B37: 1 | C37: 3 | D37: 55 | E37: 2599 | F37: 1956 | G37: 50 | H37: 1 | I37: 750000000 | J37: 500000000 | K37: 65 | L37: 53 | M37: 65 | N37: 50000000 | O37: 300000000 | P37: 350000000 | Q37: 0 | R37: 1 | S37: 1 | T37: 2 | U37: 70 | V37: 0 | W37: 0 | X37: 2 | Z37: 2 | AA37: 2 | AB37: 1 | AC37: 4 | AD37: 2 | AE37: 2 | AF37: 1 | AG37: 2 | AH37: 14 | AI37: 1
A38: 1614206 | B38: 4 | C38: 2 | D38: 6 | E38: 1811 | F38: 2010 | G38: 12 | H38: 1.8398361 | I38: 16450000 | J38: 8210000 | K38: 70 | L38: 4 | M38: 2 | N38: 2165000 | O38: 7000000 | P38: 70500000 | Q38: 0 | S38: 2 | T38: 2 | U38: 70 | V38: 0 | W38: 0 | X38: 2 | Z38: 2 | AA38: 2 | AB38: 1 | AC38: 5 | AD38: 1 | AE38: 2 | AF38: 3 | AG38: 1 | AH38: 13 | AI38: 2
A39: 1614208 | B39: 2 | C39: 1 | D39: 6 | E39: 1410 | F39: 2000 | G39: 25 | H39: 46.711292 | I39: 40000000 | J39: 15000000 | K39: 50 | L39: 6 | M39: 6 | N39: -9 | O39: 30000000 | P39: 11100000 | Q39: 0 | S39: 1 | T39: 1 | U39: 73 | V39: 0 | W39: 7 | X39: 1 | Y39: 2500000 | Z39: 1 | AA39: 1 | AB39: 1 | AC39: 3 | AD39: 3 | AE39: 0 | AF39: 0 | AG39: 0 | AH39: 6 | AI39: 2
A40: 1614212 | B40: 1 | C40: 1 | D40: 10 | E40: 1622 | F40: 2014 | G40: 10 | H40: 157.86736 | I40: 30000000 | J40: 15000000 | K40: 35 | L40: 5 | M40: 3 | N40: 10000000 | O40: 5000000 | P40: 60000000 | Q40: 0 | S40: 2 | T40: 2 | U40: 0 | V40: 0 | W40: 0 | X40: 2 | Z40: 2 | AA40: 2 | AB40: 2 | AD40: 0 | AE40: 0 | AF40: 0 | AG40: 3 | AH40: 12 | AI40: 2
...

Sheet Clean_Working
A1: Establishment_ID | B1: Region | C1: Size_Category | D1: Screener_Employees | E1: ISIC_Rev4_Code | F1: ISIC_Division | G1: Manufacturing_Subsector | H1: Year_Started | I1: Manager_Experience_Years | J1: Survey_Weight_Median | K1: Annual_Sales_2024_UGX | L1: Annual_Sales_2022_UGX | M1: Capacity_Utilization_Pct | N1: Permanent_FT_Employees_2024 | O1: Permanent_FT_Employees_2022 | P1: Labor_Cost_2024_UGX | Q1: Raw_Materials_Cost_2024_UGX | R1: Machinery_Replacement_Value_UGX | S1: Direct_Exports_Pct | T1: Monitors_Performance_Indicators | U1: Introduced_New_Product_Service | V1: Introduced_Improved_Process | W1: Working_Capital_Internal_Pct | X1: Working_Capital_Bank_Pct | Y1: Working_Capital_Supplier_Credit_Pct | Z1: Purchased_Fixed_Assets | AA1: Equipment_Investment_Raw_UGX | AB1: Has_Financial_Institution_Loan | AC1: Applied_For_Loan_2024 | AD1: Experienced_Power_Outages | AE1: Power_Outages_Per_Month_Raw | AF1: Electricity_Obstacle | AG1: Access_to_Finance_Obstacle | AH1: Workforce_Skills_Obstacle | AI1: Informal_Competition_Obstacle | AJ1: Biggest_Obstacle | AK1: Figures_Response_Quality | AL1: Establishment_Age_Years | AM1: Equipment_Investment_UGX | AN1: Power_Outages_Per_Month | AO1: Direct_Exporter | AP1: Sales_Growth_2022_2024_Pct | AQ1: Sales_CAGR_2022_2024_Pct | AR1: Employment_Growth_2022_2024_Pct | AS1: Sales_per_Employee_UGX | AT1: Labor_Cost_Pct_of_Sales | AU1: Raw_Materials_Cost_Pct_of_Sales | AV1: Machinery_Value_per_Employee_UGX | AW1: Equipment_Investment_Pct_of_Sales | AX1: Sales_Outlier_Flag | AY1: Firm_Age_Band | AZ1: Performance_Group
A2: 1614120 | B2: Eastern | C2: Large | D2: 1000 | E2: 1073 | F2: 10 | G2: Manufacture of food products | H2: 1986 | I2: 24 | J2: 1 | K2: 1200000000 | L2: 900000000 | M2: 20 | N2: 250 | O2: 180 | P2: 500000000 | Q2: 200000000 | R2: 350000000 | S2: 25 | T2: Yes | U2: No | V2: No | W2: 85 | X2: 0 | Y2: 0 | Z2: No | AB2: No | AC2: No | AD2: Yes | AE2: 6 | AF2: Moderate obstacle | AG2: Major obstacle | AH2: Moderate obstacle | AI2: Moderate obstacle | AJ2: Tax rates | AK2: Are in some case taken from books and in some case estimates | AL2: =IF(H2="","",2024-H2) -> 38 | AM2: =IFERROR(IF(Z2="No",0,IF(Z2="Yes",AA2,"")),"") -> 0 | AN2: =IFERROR(IF(AD2="No",0,IF(AD2="Yes",AE2,"")),"") -> 6 | AO2: =IF(S2>0,"Yes","No") -> Yes | AP2: =IF(OR(K2="",L2="",L2<=0),"",K2/L2-1) -> 0.33333333 | AQ2: =IF(OR(K2="",L2="",L2<=0),"",(K2/L2)^(1/2)-1) -> 0.15470054 | AR2: =IF(OR(N2="",O2="",O2<=0),"",N2/O2-1) -> 0.38888889 | AS2: =IF(OR(K2="",N2="",N2<=0),"",K2/N2) -> 4800000 | AT2: =IF(OR(P2="",K2="",K2<=0),"",P2/K2) -> 0.41666667 | AU2: =IF(OR(Q2="",K2="",K2<=0),"",Q2/K2) -> 0.16666667 | AV2: =IF(OR(R2="",N2="",N2<=0),"",R2/N2) -> 1400000 | AW2: =IFERROR(IF(Z2="No",0,IF(Z2="Yes",AM2/K2,"")),"") -> 0 | AX2: =IF(OR(K2<Outlier_Audit!$H$2,K2>Outlier_Audit!$I$2),"Review","Normal") -> Normal | AY2: =IF(AL2="","Unknown",IF(AL2<10,"<10 years",IF(AL2<20,"10-19 years",IF(AL2<30,"20-29 years","30+ years")))) -> 30+ years | AZ2: =IF(AQ2="","Missing",IF(AQ2>=EDA_Performance!$B$7,"High Growth",IF(AQ2<=EDA_Performance!$B$5,"Low Growth","Middle"))) -> Middle
A3: 1614122 | B3: Eastern | C3: Small | D3: 10 | E3: 1410 | F3: 14 | G3: Manufacture of wearing apparel | H3: 1970 | I3: 30 | J3: 55.699169 | K3: 45000000 | L3: 40000000 | M3: 70 | N3: 6 | O3: 5 | P3: 7200000 | Q3: 6000000 | R3: 30000000 | S3: 0 | T3: Not asked (survey skip: screener employment <20) | U3: No | V3: No | W3: 100 | X3: 0 | Y3: 0 | Z3: No | AB3: No | AC3: No | AD3: Yes | AE3: 2 | AF3: Very severe obstacle | AG3: Moderate obstacle | AH3: No obstacle | AI3: No obstacle | AJ3: Electricity | AK3: Are taken directly from establishment records | AL3: =IF(H3="","",2024-H3) -> 54 | AM3: =IFERROR(IF(Z3="No",0,IF(Z3="Yes",AA3,"")),"") -> 0 | AN3: =IFERROR(IF(AD3="No",0,IF(AD3="Yes",AE3,"")),"") -> 2 | AO3: =IF(S3>0,"Yes","No") -> No | AP3: =IF(OR(K3="",L3="",L3<=0),"",K3/L3-1) -> 0.125 | AQ3: =IF(OR(K3="",L3="",L3<=0),"",(K3/L3)^(1/2)-1) -> 0.060660172 | AR3: =IF(OR(N3="",O3="",O3<=0),"",N3/O3-1) -> 0.2 | AS3: =IF(OR(K3="",N3="",N3<=0),"",K3/N3) -> 7500000 | AT3: =IF(OR(P3="",K3="",K3<=0),"",P3/K3) -> 0.16 | AU3: =IF(OR(Q3="",K3="",K3<=0),"",Q3/K3) -> 0.13333333 | AV3: =IF(OR(R3="",N3="",N3<=0),"",R3/N3) -> 5000000 | AW3: =IFERROR(IF(Z3="No",0,IF(Z3="Yes",AM3/K3,"")),"") -> 0 | AX3: =IF(OR(K3<Outlier_Audit!$H$2,K3>Outlier_Audit!$I$2),"Review","Normal") -> Normal | AY3: =IF(AL3="","Unknown",IF(AL3<10,"<10 years",IF(AL3<20,"10-19 years",IF(AL3<30,"20-29 years","30+ years")))) -> 30+ years | AZ3: =IF(AQ3="","Missing",IF(AQ3>=EDA_Performance!$B$7,"High Growth",IF(AQ3<=EDA_Performance!$B$5,"Low Growth","Middle"))) -> Middle
A4: 1614124 | B4: Central | C4: Medium | D4: 100 | E4: 1073 | F4: 10 | G4: Manufacture of food products | H4: 2007 | I4: 20 | J4: 24.842424 | K4: 3000000000 | L4: 2000000000 | M4: 70 | N4: 50 | O4: 50 | P4: 700000000 | Q4: 400000000 | R4: 5000000000 | S4: 0 | T4: Yes | U4: No | V4: No | W4: 80 | X4: 0 | Y4: 0 | Z4: No | AB4: No | AC4: No | AD4: No | AF4: Moderate obstacle | AG4: Minor obstacle | AH4: Minor obstacle | AI4: Moderate obstacle | AJ4: Corruption | AK4: Are taken directly from establishment records | AL4: =IF(H4="","",2024-H4) -> 17 | AM4: =IFERROR(IF(Z4="No",0,IF(Z4="Yes",AA4,"")),"") -> 0 | AN4: =IFERROR(IF(AD4="No",0,IF(AD4="Yes",AE4,"")),"") -> 0 | AO4: =IF(S4>0,"Yes","No") -> No | AP4: =IF(OR(K4="",L4="",L4<=0),"",K4/L4-1) -> 0.5 | AQ4: =IF(OR(K4="",L4="",L4<=0),"",(K4/L4)^(1/2)-1) -> 0.22474487 | AR4: =IF(OR(N4="",O4="",O4<=0),"",N4/O4-1) -> 0 | AS4: =IF(OR(K4="",N4="",N4<=0),"",K4/N4) -> 60000000 | AT4: =IF(OR(P4="",K4="",K4<=0),"",P4/K4) -> 0.23333333 | AU4: =IF(OR(Q4="",K4="",K4<=0),"",Q4/K4) -> 0.13333333 | AV4: =IF(OR(R4="",N4="",N4<=0),"",R4/N4) -> 100000000 | AW4: =IFERROR(IF(Z4="No",0,IF(Z4="Yes",AM4/K4,"")),"") -> 0 | AX4: =IF(OR(K4<Outlier_Audit!$H$2,K4>Outlier_Audit!$I$2),"Review","Normal") -> Normal | AY4: =IF(AL4="","Unknown",IF(AL4<10,"<10 years",IF(AL4<20,"10-19 years",IF(AL4<30,"20-29 years","30+ years")))) -> 10-19 years | AZ4: =IF(AQ4="","Missing",IF(AQ4>=EDA_Performance!$B$7,"High Growth",IF(AQ4<=EDA_Performance!$B$5,"Low Growth","Middle"))) -> Middle
A5: 1614125 | B5: Central | C5: Large | D5: 110 | E5: 2100 | F5: 21 | G5: Manufacture of basic pharmaceutical products | H5: 1981 | I5: 44 | J5: 1 | K5: 13000000000 | L5: 13000000000 | M5: 90 | N5: 57 | O5: 44 | P5: 1500000000 | Q5: 6000000000 | R5: 12000000000 | S5: 1 | T5: Yes | U5: No | V5: No | W5: 100 | X5: 0 | Y5: 0 | Z5: Yes | AA5: 600000000 | AB5: Yes | AC5: No | AD5: Yes | AE5: 10 | AF5: Major obstacle | AG5: Minor obstacle | AH5: Major obstacle | AI5: Major obstacle | AJ5: Access to finance | AK5: Are taken directly from establishment records | AL5: =IF(H5="","",2024-H5) -> 43 | AM5: =IFERROR(IF(Z5="No",0,IF(Z5="Yes",AA5,"")),"") -> 600000000 | AN5: =IFERROR(IF(AD5="No",0,IF(AD5="Yes",AE5,"")),"") -> 10 | AO5: =IF(S5>0,"Yes","No") -> Yes | AP5: =IF(OR(K5="",L5="",L5<=0),"",K5/L5-1) -> 0 | AQ5: =IF(OR(K5="",L5="",L5<=0),"",(K5/L5)^(1/2)-1) -> 0 | AR5: =IF(OR(N5="",O5="",O5<=0),"",N5/O5-1) -> 0.29545455 | AS5: =IF(OR(K5="",N5="",N5<=0),"",K5/N5) -> 2.2807018e+08 | AT5: =IF(OR(P5="",K5="",K5<=0),"",P5/K5) -> 0.11538462 | AU5: =IF(OR(Q5="",K5="",K5<=0),"",Q5/K5) -> 0.46153846 | AV5: =IF(OR(R5="",N5="",N5<=0),"",R5/N5) -> 2.1052632e+08 | AW5: =IFERROR(IF(Z5="No",0,IF(Z5="Yes",AM5/K5,"")),"") -> 0.046153846 | AX5: =IF(OR(K5<Outlier_Audit!$H$2,K5>Outlier_Audit!$I$2),"Review","Normal") -> Review | AY5: =IF(AL5="","Unknown",IF(AL5<10,"<10 years",IF(AL5<20,"10-19 years",IF(AL5<30,"20-29 years","30+ years")))) -> 30+ years | AZ5: =IF(AQ5="","Missing",IF(AQ5>=EDA_Performance!$B$7,"High Growth",IF(AQ5<=EDA_Performance!$B$5,"Low Growth","Middle"))) -> Low Growth
A6: 1614130 | B6: Central | C6: Small | D6: 7 | E6: 3100 | F6: 31 | G6: Manufacture of furniture | H6: 2020 | I6: 15 | J6: 143.61815 | K6: 24000000 | L6: 17000000 | M6: 70 | N6: 5 | O6: 4 | P6: 4100000 | Q6: 12000000 | R6: 11000000 | S6: 0 | T6: Not asked (survey skip: screener employment <20) | U6: Yes | V6: Yes | W6: 60 | X6: 10 | Y6: 30 | Z6: Yes | AA6: 500000 | AB6: Yes | AC6: No | AD6: Yes | AE6: 6 | AF6: Minor obstacle | AG6: No obstacle | AH6: No obstacle | AI6: Minor obstacle | AJ6: Tax rates | AK6: Are in some case taken from books and in some case estimates | AL6: =IF(H6="","",2024-H6) -> 4 | AM6: =IFERROR(IF(Z6="No",0,IF(Z6="Yes",AA6,"")),"") -> 500000 | AN6: =IFERROR(IF(AD6="No",0,IF(AD6="Yes",AE6,"")),"") -> 6 | AO6: =IF(S6>0,"Yes","No") -> No | AP6: =IF(OR(K6="",L6="",L6<=0),"",K6/L6-1) -> 0.41176471 | AQ6: =IF(OR(K6="",L6="",L6<=0),"",(K6/L6)^(1/2)-1) -> 0.18817705 | AR6: =IF(OR(N6="",O6="",O6<=0),"",N6/O6-1) -> 0.25 | AS6: =IF(OR(K6="",N6="",N6<=0),"",K6/N6) -> 4800000 | AT6: =IF(OR(P6="",K6="",K6<=0),"",P6/K6) -> 0.17083333 | AU6: =IF(OR(Q6="",K6="",K6<=0),"",Q6/K6) -> 0.5 | AV6: =IF(OR(R6="",N6="",N6<=0),"",R6/N6) -> 2200000 | AW6: =IFERROR(IF(Z6="No",0,IF(Z6="Yes",AM6/K6,"")),"") -> 0.020833333 | AX6: =IF(OR(K6<Outlier_Audit!$H$2,K6>Outlier_Audit!$I$2),"Review","Normal") -> Normal | AY6: =IF(AL6="","Unknown",IF(AL6<10,"<10 years",IF(AL6<20,"10-19 years",IF(AL6<30,"20-29 years","30+ years")))) -> <10 years | AZ6: =IF(AQ6="","Missing",IF(AQ6>=EDA_Performance!$B$7,"High Growth",IF(AQ6<=EDA_Performance!$B$5,"Low Growth","Middle"))) -> Middle
A7: 1614131 | B7: Central | C7: Small | D7: 16 | E7: 1811 | F7: 18 | G7: Printing and reproduction of recorded media | H7: 1985 | I7: 30 | J7: 157.86736 | K7: 100000000 | L7: 80000000 | M7: 20 | N7: 16 | O7: 16 | P7: 5000000 | Q7: 20000000 | R7: 350000000 | S7: 0 | T7: Not asked (survey skip: screener employment <20) | U7: No | V7: No | W7: 80 | X7: 0 | Y7: 0 | Z7: No | AB7: No | AC7: No | AD7: No | AF7: Minor obstacle | AG7: No obstacle | AH7: No obstacle | AI7: No obstacle | AJ7: Electricity | AK7: Are in some case taken from books and in some case estimates | AL7: =IF(H7="","",2024-H7) -> 39 | AM7: =IFERROR(IF(Z7="No",0,IF(Z7="Yes",AA7,"")),"") -> 0 | AN7: =IFERROR(IF(AD7="No",0,IF(AD7="Yes",AE7,"")),"") -> 0 | AO7: =IF(S7>0,"Yes","No") -> No | AP7: =IF(OR(K7="",L7="",L7<=0),"",K7/L7-1) -> 0.25 | AQ7: =IF(OR(K7="",L7="",L7<=0),"",(K7/L7)^(1/2)-1) -> 0.11803399 | AR7: =IF(OR(N7="",O7="",O7<=0),"",N7/O7-1) -> 0 | AS7: =IF(OR(K7="",N7="",N7<=0),"",K7/N7) -> 6250000 | AT7: =IF(OR(P7="",K7="",K7<=0),"",P7/K7) -> 0.05 | AU7: =IF(OR(Q7="",K7="",K7<=0),"",Q7/K7) -> 0.2 | AV7: =IF(OR(R7="",N7="",N7<=0),"",R7/N7) -> 21875000 | AW7: =IFERROR(IF(Z7="No",0,IF(Z7="Yes",AM7/K7,"")),"") -> 0 | AX7: =IF(OR(K7<Outlier_Audit!$H$2,K7>Outlier_Audit!$I$2),"Review","Normal") -> Normal | AY7: =IF(AL7="","Unknown",IF(AL7<10,"<10 years",IF(AL7<20,"10-19 years",IF(AL7<30,"20-29 years","30+ years")))) -> 30+ years | AZ7: =IF(AQ7="","Missing",IF(AQ7>=EDA_Performance!$B$7,"High Growth",IF(AQ7<=EDA_Performance!$B$5,"Low Growth","Middle"))) -> Middle
A8: 1614136 | B8: Central | C8: Large | D8: 1850 | E8: 2410 | F8: 24 | G8: Manufacture of basic metals | H8: 1983 | I8: 42 | J8: 1 | K8: 6000000000000 | L8: 4000000000000 | M8: 92 | N8: 2000 | O8: 1800 | P8: 1000000000000 | Q8: 3000000000000 | R8: 1000000000000 | S8: 35 | T8: Yes | U8: Yes | V8: Yes | W8: 35 | X8: 30 | Y8: 25 | Z8: Yes | AA8: 1000000000000 | AB8: Yes | AC8: Yes | AD8: Yes | AE8: 2 | AF8: Moderate obstacle | AG8: Moderate obstacle | AH8: Minor obstacle | AI8: Moderate obstacle | AJ8: Tax rates | AK8: Are taken directly from establishment records | AL8: =IF(H8="","",2024-H8) -> 41 | AM8: =IFERROR(IF(Z8="No",0,IF(Z8="Yes",AA8,"")),"") -> 1000000000000 | AN8: =IFERROR(IF(AD8="No",0,IF(AD8="Yes",AE8,"")),"") -> 2 | AO8: =IF(S8>0,"Yes","No") -> Yes | AP8: =IF(OR(K8="",L8="",L8<=0),"",K8/L8-1) -> 0.5 | AQ8: =IF(OR(K8="",L8="",L8<=0),"",(K8/L8)^(1/2)-1) -> 0.22474487 | AR8: =IF(OR(N8="",O8="",O8<=0),"",N8/O8-1) -> 0.11111111 | AS8: =IF(OR(K8="",N8="",N8<=0),"",K8/N8) -> 3000000000 | AT8: =IF(OR(P8="",K8="",K8<=0),"",P8/K8) -> 0.16666667 | AU8: =IF(OR(Q8="",K8="",K8<=0),"",Q8/K8) -> 0.5 | AV8: =IF(OR(R8="",N8="",N8<=0),"",R8/N8) -> 500000000 | AW8: =IFERROR(IF(Z8="No",0,IF(Z8="Yes",AM8/K8,"")),"") -> 0.16666667 | AX8: =IF(OR(K8<Outlier_Audit!$H$2,K8>Outlier_Audit!$I$2),"Review","Normal") -> Review | AY8: =IF(AL8="","Unknown",IF(AL8<10,"<10 years",IF(AL8<20,"10-19 years",IF(AL8<30,"20-29 years","30+ years")))) -> 30+ years | AZ8: =IF(AQ8="","Missing",IF(AQ8>=EDA_Performance!$B$7,"High Growth",IF(AQ8<=EDA_Performance!$B$5,"Low Growth","Middle"))) -> Middle
A9: 1614138 | B9: Eastern | C9: Small | D9: 9 | E9: 1079 | F9: 10 | G9: Manufacture of food products | H9: 1992 | I9: 30 | J9: 1.7886078 | K9: 38000000 | L9: 6000000 | M9: 100 | N9: 9 | O9: 9 | P9: 10000000 | R9: 15000000 | S9: 0 | T9: Not asked (survey skip: screener employment <20) | U9: No | V9: No | W9: 40 | X9: 0 | Y9: 0 | Z9: No | AB9: No | AC9: No | AD9: Yes | AE9: 8 | AF9: Very severe obstacle | AG9: Moderate obstacle | AH9: No obstacle | AI9: Very severe obstacle | AJ9: Access to finance | AK9: Are in some case taken from books and in some case estimates | AL9: =IF(H9="","",2024-H9) -> 32 | AM9: =IFERROR(IF(Z9="No",0,IF(Z9="Yes",AA9,"")),"") -> 0 | AN9: =IFERROR(IF(AD9="No",0,IF(AD9="Yes",AE9,"")),"") -> 8 | AO9: =IF(S9>0,"Yes","No") -> No | AP9: =IF(OR(K9="",L9="",L9<=0),"",K9/L9-1) -> 5.3333333 | AQ9: =IF(OR(K9="",L9="",L9<=0),"",(K9/L9)^(1/2)-1) -> 1.5166115 | AR9: =IF(OR(N9="",O9="",O9<=0),"",N9/O9-1) -> 0 | AS9: =IF(OR(K9="",N9="",N9<=0),"",K9/N9) -> 4222222.2 | AT9: =IF(OR(P9="",K9="",K9<=0),"",P9/K9) -> 0.26315789 | AU9: =IF(OR(Q9="",K9="",K9<=0),"",Q9/K9) | AV9: =IF(OR(R9="",N9="",N9<=0),"",R9/N9) -> 1666666.7 | AW9: =IFERROR(IF(Z9="No",0,IF(Z9="Yes",AM9/K9,"")),"") -> 0 | AX9: =IF(OR(K9<Outlier_Audit!$H$2,K9>Outlier_Audit!$I$2),"Review","Normal") -> Normal | AY9: =IF(AL9="","Unknown",IF(AL9<10,"<10 years",IF(AL9<20,"10-19 years",IF(AL9<30,"20-29 years","30+ years")))) -> 30+ years | AZ9: =IF(AQ9="","Missing",IF(AQ9>=EDA_Performance!$B$7,"High Growth",IF(AQ9<=EDA_Performance!$B$5,"Low Growth","Middle"))) -> High Growth
A10: 1614139 | B10: Western | C10: Small | D10: 5 | E10: 3100 | F10: 31 | G10: Manufacture of furniture | H10: 2002 | I10: 24 | J10: 68.62606 | K10: 40000000 | L10: 22000000 | M10: 4 | N10: 5 | O10: 5 | P10: 12000000 | Q10: 16000000 | R10: 24200000 | S10: 0 | T10: Not asked (survey skip: screener employment <20) | U10: No | V10: No | W10: 20 | X10: 60 | Y10: 0 | Z10: Yes | AA10: 1000000 | AB10: Yes | AC10: No | AD10: Yes | AE10: 5 | AF10: Major obstacle | AG10: Very severe obstacle | AH10: No obstacle | AI10: Minor obstacle | AJ10: Access to finance | AK10: Are estimates computed with some precision | AL10: =IF(H10="","",2024-H10) -> 22 | AM10: =IFERROR(IF(Z10="No",0,IF(Z10="Yes",AA10,"")),"") -> 1000000 | AN10: =IFERROR(IF(AD10="No",0,IF(AD10="Yes",AE10,"")),"") -> 5 | AO10: =IF(S10>0,"Yes","No") -> No | AP10: =IF(OR(K10="",L10="",L10<=0),"",K10/L10-1) -> 0.81818182 | AQ10: =IF(OR(K10="",L10="",L10<=0),"",(K10/L10)^(1/2)-1) -> 0.34839972 | AR10: =IF(OR(N10="",O10="",O10<=0),"",N10/O10-1) -> 0 | AS10: =IF(OR(K10="",N10="",N10<=0),"",K10/N10) -> 8000000 | AT10: =IF(OR(P10="",K10="",K10<=0),"",P10/K10) -> 0.3 | AU10: =IF(OR(Q10="",K10="",K10<=0),"",Q10/K10) -> 0.4 | AV10: =IF(OR(R10="",N10="",N10<=0),"",R10/N10) -> 4840000 | AW10: =IFERROR(IF(Z10="No",0,IF(Z10="Yes",AM10/K10,"")),"") -> 0.025 | AX10: =IF(OR(K10<Outlier_Audit!$H$2,K10>Outlier_Audit!$I$2),"Review","Normal") -> Normal | AY10: =IF(AL10="","Unknown",IF(AL10<10,"<10 years",IF(AL10<20,"10-19 years",IF(AL10<30,"20-29 years","30+ years")))) -> 20-29 years | AZ10: =IF(AQ10="","Missing",IF(AQ10>=EDA_Performance!$B$7,"High Growth",IF(AQ10<=EDA_Performance!$B$5,"Low Growth","Middle"))) -> High Growth
A11: 1614143 | B11: Central | C11: Small | D11: 6 | E11: 2599 | F11: 25 | G11: Manufacture of fabricated metal products | H11: 1987 | I11: 35 | J11: 157.86736 | K11: 10000000 | L11: 10000000 | M11: 100 | N11: 6 | O11: 6 | P11: 6000000 | Q11: 3000000 | R11: 7000000 | S11: 0 | T11: Not asked (survey skip: screener employment <20) | U11: No | V11: No | W11: 80 | X11: 10 | Y11: 0 | Z11: No | AB11: No | AC11: Yes | AD11: Yes | AE11: 2 | AF11: Minor obstacle | AG11: Major obstacle | AH11: No obstacle | AI11: Minor obstacle | AJ11: Access to finance | AK11: Are in some case taken from books and in some case estimates | AL11: =IF(H11="","",2024-H11) -> 37 | AM11: =IFERROR(IF(Z11="No",0,IF(Z11="Yes",AA11,"")),"") -> 0 | AN11: =IFERROR(IF(AD11="No",0,IF(AD11="Yes",AE11,"")),"") -> 2 | AO11: =IF(S11>0,"Yes","No") -> No | AP11: =IF(OR(K11="",L11="",L11<=0),"",K11/L11-1) -> 0 | AQ11: =IF(OR(K11="",L11="",L11<=0),"",(K11/L11)^(1/2)-1) -> 0 | AR11: =IF(OR(N11="",O11="",O11<=0),"",N11/O11-1) -> 0 | AS11: =IF(OR(K11="",N11="",N11<=0),"",K11/N11) -> 1666666.7 | AT11: =IF(OR(P11="",K11="",K11<=0),"",P11/K11) -> 0.6 | AU11: =IF(OR(Q11="",K11="",K11<=0),"",Q11/K11) -> 0.3 | AV11: =IF(OR(R11="",N11="",N11<=0),"",R11/N11) -> 1166666.7 | AW11: =IFERROR(IF(Z11="No",0,IF(Z11="Yes",AM11/K11,"")),"") -> 0 | AX11: =IF(OR(K11<Outlier_Audit!$H$2,K11>Outlier_Audit!$I$2),"Review","Normal") -> Normal | AY11: =IF(AL11="","Unknown",IF(AL11<10,"<10 years",IF(AL11<20,"10-19 years",IF(AL11<30,"20-29 years","30+ years")))) -> 30+ years | AZ11: =IF(AQ11="","Missing",IF(AQ11>=EDA_Performance!$B$7,"High Growth",IF(AQ11<=EDA_Performance!$B$5,"Low Growth","Middle"))) -> Low Growth
A12: 1614144 | B12: Central | C12: Small | D12: 50 | E12: 1812 | F12: 18 | G12: Printing and reproduction of recorded media | H12: 1995 | I12: 17 | J12: 585.95532 | K12: 300000000 | L12: 110000000 | M12: 95 | N12: 40 | O12: 20 | P12: 30000000 | Q12: 40000000 | R12: 1000000000 | S12: 10 | T12: Yes | U12: No | V12: Yes | W12: 80 | X12: 10 | Y12: 0 | Z12: Yes | AA12: 300000000 | AB12: Yes | AC12: No | AD12: Yes | AE12: 6 | AF12: Minor obstacle | AG12: No obstacle | AH12: No obstacle | AI12: Minor obstacle | AJ12: Customs and trade regulations | AK12: Are estimates computed with some precision | AL12: =IF(H12="","",2024-H12) -> 29 | AM12: =IFERROR(IF(Z12="No",0,IF(Z12="Yes",AA12,"")),"") -> 300000000 | AN12: =IFERROR(IF(AD12="No",0,IF(AD12="Yes",AE12,"")),"") -> 6 | AO12: =IF(S12>0,"Yes","No") -> Yes | AP12: =IF(OR(K12="",L12="",L12<=0),"",K12/L12-1) -> 1.7272727 | AQ12: =IF(OR(K12="",L12="",L12<=0),"",(K12/L12)^(1/2)-1) -> 0.65144565 | AR12: =IF(OR(N12="",O12="",O12<=0),"",N12/O12-1) -> 1 | AS12: =IF(OR(K12="",N12="",N12<=0),"",K12/N12) -> 7500000 | AT12: =IF(OR(P12="",K12="",K12<=0),"",P12/K12) -> 0.1 | AU12: =IF(OR(Q12="",K12="",K12<=0),"",Q12/K12) -> 0.13333333 | AV12: =IF(OR(R12="",N12="",N12<=0),"",R12/N12) -> 25000000 | AW12: =IFERROR(IF(Z12="No",0,IF(Z12="Yes",AM12/K12,"")),"") -> 1 | AX12: =IF(OR(K12<Outlier_Audit!$H$2,K12>Outlier_Audit!$I$2),"Review","Normal") -> Normal | AY12: =IF(AL12="","Unknown",IF(AL12<10,"<10 years",IF(AL12<20,"10-19 years",IF(AL12<30,"20-29 years","30+ years")))) -> 20-29 years | AZ12: =IF(AQ12="","Missing",IF(AQ12>=EDA_Performance!$B$7,"High Growth",IF(AQ12<=EDA_Performance!$B$5,"Low Growth","Middle"))) -> High Growth
A13: 1614146 | B13: Central | C13: Small | D13: 80 | E13: 2023 | F13: 20 | G13: Manufacture of chemicals and chemical products | H13: 2005 | I13: 20 | J13: 585.95532 | K13: 2000000000 | L13: 1000000000 | M13: 70 | N13: 80 | O13: 40 | P13: 200000000 | Q13: 800000000 | R13: 700000000 | S13: 30 | T13: Yes | U13: Yes | V13: Yes | W13: 40 | X13: 5 | Y13: 0 | Z13: Yes | AA13: 80000000 | AB13: Yes | AC13: No | AD13: Yes | AE13: 4 | AF13: Major obstacle | AG13: No obstacle | AH13: No obstacle | AI13: No obstacle | AJ13: Tax rates | AK13: Are in some case taken from books and in some case estimates | AL13: =IF(H13="","",2024-H13) -> 19 | AM13: =IFERROR(IF(Z13="No",0,IF(Z13="Yes",AA13,"")),"") -> 80000000 | AN13: =IFERROR(IF(AD13="No",0,IF(AD13="Yes",AE13,"")),"") -> 4 | AO13: =IF(S13>0,"Yes","No") -> Yes | AP13: =IF(OR(K13="",L13="",L13<=0),"",K13/L13-1) -> 1 | AQ13: =IF(OR(K13="",L13="",L13<=0),"",(K13/L13)^(1/2)-1) -> 0.41421356 | AR13: =IF(OR(N13="",O13="",O13<=0),"",N13/O13-1) -> 1 | AS13: =IF(OR(K13="",N13="",N13<=0),"",K13/N13) -> 25000000 | AT13: =IF(OR(P13="",K13="",K13<=0),"",P13/K13) -> 0.1 | AU13: =IF(OR(Q13="",K13="",K13<=0),"",Q13/K13) -> 0.4 | AV13: =IF(OR(R13="",N13="",N13<=0),"",R13/N13) -> 8750000 | AW13: =IFERROR(IF(Z13="No",0,IF(Z13="Yes",AM13/K13,"")),"") -> 0.04 | AX13: =IF(OR(K13<Outlier_Audit!$H$2,K13>Outlier_Audit!$I$2),"Review","Normal") -> Normal | AY13: =IF(AL13="","Unknown",IF(AL13<10,"<10 years",IF(AL13<20,"10-19 years",IF(AL13<30,"20-29 years","30+ years")))) -> 10-19 years | AZ13: =IF(AQ13="","Missing",IF(AQ13>=EDA_Performance!$B$7,"High Growth",IF(AQ13<=EDA_Performance!$B$5,"Low Growth","Middle"))) -> High Growth
A14: 1614147 | B14: Eastern | C14: Large | D14: 100 | E14: 1079 | F14: 10 | G14: Manufacture of food products | H14: 1982 | I14: 43 | J14: 1 | K14: 3000000000 | L14: 2500000000 | M14: 30 | N14: 35 | O14: 35 | P14: 300000000 | Q14: 900000000 | R14: 600000000 | S14: 10 | T14: Yes | U14: No | V14: Yes | W14: 100 | X14: 0 | Y14: 0 | Z14: No | AB14: No | AC14: No | AD14: Yes | AE14: 5 | AF14: Major obstacle | AG14: Minor obstacle | AH14: Moderate obstacle | AI14: Very severe obstacle | AJ14: Practices of competitors in the informal sector | AK14: Are in some case taken from books and in some case estimates | AL14: =IF(H14="","",2024-H14) -> 42 | AM14: =IFERROR(IF(Z14="No",0,IF(Z14="Yes",AA14,"")),"") -> 0 | AN14: =IFERROR(IF(AD14="No",0,IF(AD14="Yes",AE14,"")),"") -> 5 | AO14: =IF(S14>0,"Yes","No") -> Yes | AP14: =IF(OR(K14="",L14="",L14<=0),"",K14/L14-1) -> 0.2 | AQ14: =IF(OR(K14="",L14="",L14<=0),"",(K14/L14)^(1/2)-1) -> 0.095445115 | AR14: =IF(OR(N14="",O14="",O14<=0),"",N14/O14-1) -> 0 | AS14: =IF(OR(K14="",N14="",N14<=0),"",K14/N14) -> 85714286 | AT14: =IF(OR(P14="",K14="",K14<=0),"",P14/K14) -> 0.1 | AU14: =IF(OR(Q14="",K14="",K14<=0),"",Q14/K14) -> 0.3 | AV14: =IF(OR(R14="",N14="",N14<=0),"",R14/N14) -> 17142857 | AW14: =IFERROR(IF(Z14="No",0,IF(Z14="Yes",AM14/K14,"")),"") -> 0 | AX14: =IF(OR(K14<Outlier_Audit!$H$2,K14>Outlier_Audit!$I$2),"Review","Normal") -> Normal | AY14: =IF(AL14="","Unknown",IF(AL14<10,"<10 years",IF(AL14<20,"10-19 years",IF(AL14<30,"20-29 years","30+ years")))) -> 30+ years | AZ14: =IF(AQ14="","Missing",IF(AQ14>=EDA_Performance!$B$7,"High Growth",IF(AQ14<=EDA_Performance!$B$5,"Low Growth","Middle"))) -> Middle
A15: 1614149 | B15: Northern | C15: Medium | D15: 10 | E15: 1040 | F15: 10 | G15: Manufacture of food products | H15: 2013 | I15: 10 | J15: 1.826539 | K15: 300000000 | L15: 250000000 | M15: 100 | N15: 15 | O15: 10 | P15: 70000000 | Q15: 100000000 | R15: 400000000 | S15: 0 | T15: Not asked (survey skip: screener employment <20) | U15: No | V15: No | W15: 40 | X15: 0 | Y15: 40 | Z15: No | AB15: No | AC15: No | AD15: Yes | AE15: 7 | AF15: Moderate obstacle | AG15: Minor obstacle | AH15: No obstacle | AI15: Very severe obstacle | AJ15: Practices of competitors in the informal sector | AK15: Are in some case taken from books and in some case estimates | AL15: =IF(H15="","",2024-H15) -> 11 | AM15: =IFERROR(IF(Z15="No",0,IF(Z15="Yes",AA15,"")),"") -> 0 | AN15: =IFERROR(IF(AD15="No",0,IF(AD15="Yes",AE15,"")),"") -> 7 | AO15: =IF(S15>0,"Yes","No") -> No | AP15: =IF(OR(K15="",L15="",L15<=0),"",K15/L15-1) -> 0.2 | AQ15: =IF(OR(K15="",L15="",L15<=0),"",(K15/L15)^(1/2)-1) -> 0.095445115 | AR15: =IF(OR(N15="",O15="",O15<=0),"",N15/O15-1) -> 0.5 | AS15: =IF(OR(K15="",N15="",N15<=0),"",K15/N15) -> 20000000 | AT15: =IF(OR(P15="",K15="",K15<=0),"",P15/K15) -> 0.23333333 | AU15: =IF(OR(Q15="",K15="",K15<=0),"",Q15/K15) -> 0.33333333 | AV15: =IF(OR(R15="",N15="",N15<=0),"",R15/N15) -> 26666667 | AW15: =IFERROR(IF(Z15="No",0,IF(Z15="Yes",AM15/K15,"")),"") -> 0 | AX15: =IF(OR(K15<Outlier_Audit!$H$2,K15>Outlier_Audit!$I$2),"Review","Normal") -> Normal | AY15: =IF(AL15="","Unknown",IF(AL15<10,"<10 years",IF(AL15<20,"10-19 years",IF(AL15<30,"20-29 years","30+ years")))) -> 10-19 years | AZ15: =IF(AQ15="","Missing",IF(AQ15>=EDA_Performance!$B$7,"High Growth",IF(AQ15<=EDA_Performance!$B$5,"Low Growth","Middle"))) -> Middle
A16: 1614151 | B16: Central | C16: Large | D16: 355 | E16: 1079 | F16: 10 | G16: Manufacture of food products | H16: 1994 | I16: 25 | J16: 1 | K16: 68000000000 | L16: 67000000000 | M16: 69 | N16: 124 | O16: 118 | P16: 4140000000 | Q16: 37820000000 | R16: 95000000000 | S16: 1 | T16: Yes | U16: Yes | V16: No | W16: 100 | X16: 0 | Y16: 0 | Z16: No | AB16: No | AC16: No | AD16: Yes | AE16: 10 | AF16: Very severe obstacle | AG16: Minor obstacle | AH16: Minor obstacle | AI16: Very severe obstacle | AJ16: Electricity | AK16: Are in some case taken from books and in some case estimates | AL16: =IF(H16="","",2024-H16) -> 30 | AM16: =IFERROR(IF(Z16="No",0,IF(Z16="Yes",AA16,"")),"") -> 0 | AN16: =IFERROR(IF(AD16="No",0,IF(AD16="Yes",AE16,"")),"") -> 10 | AO16: =IF(S16>0,"Yes","No") -> Yes | AP16: =IF(OR(K16="",L16="",L16<=0),"",K16/L16-1) -> 0.014925373 | AQ16: =IF(OR(K16="",L16="",L16<=0),"",(K16/L16)^(1/2)-1) -> 0.0074350466 | AR16: =IF(OR(N16="",O16="",O16<=0),"",N16/O16-1) -> 0.050847458 | AS16: =IF(OR(K16="",N16="",N16<=0),"",K16/N16) -> 5.483871e+08 | AT16: =IF(OR(P16="",K16="",K16<=0),"",P16/K16) -> 0.060882353 | AU16: =IF(OR(Q16="",K16="",K16<=0),"",Q16/K16) -> 0.55617647 | AV16: =IF(OR(R16="",N16="",N16<=0),"",R16/N16) -> 7.6612903e+08 | AW16: =IFERROR(IF(Z16="No",0,IF(Z16="Yes",AM16/K16,"")),"") -> 0 | AX16: =IF(OR(K16<Outlier_Audit!$H$2,K16>Outlier_Audit!$I$2),"Review","Normal") -> Review | AY16: =IF(AL16="","Unknown",IF(AL16<10,"<10 years",IF(AL16<20,"10-19 years",IF(AL16<30,"20-29 years","30+ years")))) -> 30+ years | AZ16: =IF(AQ16="","Missing",IF(AQ16>=EDA_Performance!$B$7,"High Growth",IF(AQ16<=EDA_Performance!$B$5,"Low Growth","Middle"))) -> Low Growth
A17: 1614153 | B17: Eastern | C17: Medium | D17: 8 | E17: 3100 | F17: 31 | G17: Manufacture of furniture | H17: 2021 | I17: 5 | J17: 3.0692382 | K17: 60000000 | L17: 30000000 | M17: 70 | N17: 8 | O17: 8 | P17: 20000000 | Q17: 35000000 | S17: 0 | T17: Not asked (survey skip: screener employment <20) | U17: No | V17: No | W17: 30 | X17: 25 | Y17: 20 | Z17: No | AB17: Yes | AC17: No | AD17: Yes | AE17: 6 | AF17: Minor obstacle | AG17: Major obstacle | AH17: No obstacle | AI17: Major obstacle | AJ17: Tax rates | AK17: Are taken directly from establishment records | AL17: =IF(H17="","",2024-H17) -> 3 | AM17: =IFERROR(IF(Z17="No",0,IF(Z17="Yes",AA17,"")),"") -> 0 | AN17: =IFERROR(IF(AD17="No",0,IF(AD17="Yes",AE17,"")),"") -> 6 | AO17: =IF(S17>0,"Yes","No") -> No | AP17: =IF(OR(K17="",L17="",L17<=0),"",K17/L17-1) -> 1 | AQ17: =IF(OR(K17="",L17="",L17<=0),"",(K17/L17)^(1/2)-1) -> 0.41421356 | AR17: =IF(OR(N17="",O17="",O17<=0),"",N17/O17-1) -> 0 | AS17: =IF(OR(K17="",N17="",N17<=0),"",K17/N17) -> 7500000 | AT17: =IF(OR(P17="",K17="",K17<=0),"",P17/K17) -> 0.33333333 | AU17: =IF(OR(Q17="",K17="",K17<=0),"",Q17/K17) -> 0.58333333 | AV17: =IF(OR(R17="",N17="",N17<=0),"",R17/N17) | AW17: =IFERROR(IF(Z17="No",0,IF(Z17="Yes",AM17/K17,"")),"") -> 0 | AX17: =IF(OR(K17<Outlier_Audit!$H$2,K17>Outlier_Audit!$I$2),"Review","Normal") -> Normal | AY17: =IF(AL17="","Unknown",IF(AL17<10,"<10 years",IF(AL17<20,"10-19 years",IF(AL17<30,"20-29 years","30+ years")))) -> <10 years | AZ17: =IF(AQ17="","Missing",IF(AQ17>=EDA_Performance!$B$7,"High Growth",IF(AQ17<=EDA_Performance!$B$5,"Low Growth","Middle"))) -> High Growth
A18: 1614155 | B18: Western | C18: Medium | D18: 16 | E18: 1410 | F18: 14 | G18: Manufacture of wearing apparel | H18: 1990 | I18: 35 | J18: 2.4641058 | K18: 57242000 | L18: 35000000 | M18: 13 | N18: 6 | O18: 6 | P18: 18000000 | Q18: 22500000 | R18: 26500000 | S18: 0 | T18: Not asked (survey skip: screener employment <20) | U18: No | V18: No | W18: 50 | X18: 10 | Y18: 10 | Z18: No | AB18: Yes | AC18: Yes | AD18: Yes | AE18: 0 | AF18: Minor obstacle | AG18: Major obstacle | AH18: No obstacle | AI18: Minor obstacle | AJ18: Access to finance | AK18: Are in some case taken from books and in some case estimates | AL18: =IF(H18="","",2024-H18) -> 34 | AM18: =IFERROR(IF(Z18="No",0,IF(Z18="Yes",AA18,"")),"") -> 0 | AN18: =IFERROR(IF(AD18="No",0,IF(AD18="Yes",AE18,"")),"") -> 0 | AO18: =IF(S18>0,"Yes","No") -> No | AP18: =IF(OR(K18="",L18="",L18<=0),"",K18/L18-1) -> 0.63548571 | AQ18: =IF(OR(K18="",L18="",L18<=0),"",(K18/L18)^(1/2)-1) -> 0.2788611 | AR18: =IF(OR(N18="",O18="",O18<=0),"",N18/O18-1) -> 0 | AS18: =IF(OR(K18="",N18="",N18<=0),"",K18/N18) -> 9540333.3 | AT18: =IF(OR(P18="",K18="",K18<=0),"",P18/K18) -> 0.31445442 | AU18: =IF(OR(Q18="",K18="",K18<=0),"",Q18/K18) -> 0.39306803 | AV18: =IF(OR(R18="",N18="",N18<=0),"",R18/N18) -> 4416666.7 | AW18: =IFERROR(IF(Z18="No",0,IF(Z18="Yes",AM18/K18,"")),"") -> 0 | AX18: =IF(OR(K18<Outlier_Audit!$H$2,K18>Outlier_Audit!$I$2),"Review","Normal") -> Normal | AY18: =IF(AL18="","Unknown",IF(AL18<10,"<10 years",IF(AL18<20,"10-19 years",IF(AL18<30,"20-29 years","30+ years")))) -> 30+ years | AZ18: =IF(AQ18="","Missing",IF(AQ18>=EDA_Performance!$B$7,"High Growth",IF(AQ18<=EDA_Performance!$B$5,"Low Growth","Middle"))) -> High Growth
A19: 1614157 | B19: Eastern | C19: Small | D19: 7 | E19: 1061 | F19: 10 | G19: Manufacture of food products | H19: 2015 | I19: 10 | J19: 26.253841 | K19: 32000000 | L19: 28000000 | M19: 65 | N19: 7 | O19: 7 | P19: 12000000 | Q19: 18000000 | R19: 20000000 | S19: 0 | T19: Not asked (survey skip: screener employment <20) | U19: No | V19: No | W19: 80 | X19: 0 | Y19: 0 | Z19: No | AB19: No | AC19: No | AD19: Yes | AE19: 8 | AF19: Moderate obstacle | AG19: Major obstacle | AH19: No obstacle | AI19: Major obstacle | AJ19: Tax rates | AK19: Are estimates computed with some precision | AL19: =IF(H19="","",2024-H19) -> 9 | AM19: =IFERROR(IF(Z19="No",0,IF(Z19="Yes",AA19,"")),"") -> 0 | AN19: =IFERROR(IF(AD19="No",0,IF(AD19="Yes",AE19,"")),"") -> 8 | AO19: =IF(S19>0,"Yes","No") -> No | AP19: =IF(OR(K19="",L19="",L19<=0),"",K19/L19-1) -> 0.14285714 | AQ19: =IF(OR(K19="",L19="",L19<=0),"",(K19/L19)^(1/2)-1) -> 0.069044968 | AR19: =IF(OR(N19="",O19="",O19<=0),"",N19/O19-1) -> 0 | AS19: =IF(OR(K19="",N19="",N19<=0),"",K19/N19) -> 4571428.6 | AT19: =IF(OR(P19="",K19="",K19<=0),"",P19/K19) -> 0.375 | AU19: =IF(OR(Q19="",K19="",K19<=0),"",Q19/K19) -> 0.5625 | AV19: =IF(OR(R19="",N19="",N19<=0),"",R19/N19) -> 2857142.9 | AW19: =IFERROR(IF(Z19="No",0,IF(Z19="Yes",AM19/K19,"")),"") -> 0 | AX19: =IF(OR(K19<Outlier_Audit!$H$2,K19>Outlier_Audit!$I$2),"Review","Normal") -> Normal | AY19: =IF(AL19="","Unknown",IF(AL19<10,"<10 years",IF(AL19<20,"10-19 years",IF(AL19<30,"20-29 years","30+ years")))) -> <10 years | AZ19: =IF(AQ19="","Missing",IF(AQ19>=EDA_Performance!$B$7,"High Growth",IF(AQ19<=EDA_Performance!$B$5,"Low Growth","Middle"))) -> Middle
A20: 1614160 | B20: Western | C20: Small | D20: 16 | E20: 3100 | F20: 31 | G20: Manufacture of furniture | H20: 2009 | I20: 20 | J20: 68.62606 | K20: 45000000 | L20: 18000000 | M20: 60 | N20: 12 | O20: 8 | Q20: 30000000 | R20: 50000000 | S20: 0 | T20: Not asked (survey skip: screener employment <20) | U20: No | V20: Yes | W20: 50 | X20: 25 | Y20: 0 | Z20: No | AB20: Yes | AC20: Yes | AD20: Yes | AE20: 30 | AF20: Major obstacle | AG20: Moderate obstacle | AH20: Minor obstacle | AI20: Major obstacle | AJ20: Electricity | AK20: Are estimates computed with some precision | AL20: =IF(H20="","",2024-H20) -> 15 | AM20: =IFERROR(IF(Z20="No",0,IF(Z20="Yes",AA20,"")),"") -> 0 | AN20: =IFERROR(IF(AD20="No",0,IF(AD20="Yes",AE20,"")),"") -> 30 | AO20: =IF(S20>0,"Yes","No") -> No | AP20: =IF(OR(K20="",L20="",L20<=0),"",K20/L20-1) -> 1.5 | AQ20: =IF(OR(K20="",L20="",L20<=0),"",(K20/L20)^(1/2)-1) -> 0.58113883 | AR20: =IF(OR(N20="",O20="",O20<=0),"",N20/O20-1) -> 0.5 | AS20: =IF(OR(K20="",N20="",N20<=0),"",K20/N20) -> 3750000 | AT20: =IF(OR(P20="",K20="",K20<=0),"",P20/K20) | AU20: =IF(OR(Q20="",K20="",K20<=0),"",Q20/K20) -> 0.66666667 | AV20: =IF(OR(R20="",N20="",N20<=0),"",R20/N20) -> 4166666.7 | AW20: =IFERROR(IF(Z20="No",0,IF(Z20="Yes",AM20/K20,"")),"") -> 0 | AX20: =IF(OR(K20<Outlier_Audit!$H$2,K20>Outlier_Audit!$I$2),"Review","Normal") -> Normal | AY20: =IF(AL20="","Unknown",IF(AL20<10,"<10 years",IF(AL20<20,"10-19 years",IF(AL20<30,"20-29 years","30+ years")))) -> 10-19 years | AZ20: =IF(AQ20="","Missing",IF(AQ20>=EDA_Performance!$B$7,"High Growth",IF(AQ20<=EDA_Performance!$B$5,"Low Growth","Middle"))) -> High Growth
A21: 1614161 | B21: Eastern | C21: Small | D21: 7 | E21: 1061 | F21: 10 | G21: Manufacture of food products | H21: 2000 | I21: 25 | J21: 118.82497 | K21: 154000000 | L21: 144000000 | M21: 100 | N21: 7 | O21: 7 | P21: 21600000 | Q21: 35000000 | R21: 300000000 | S21: 0 | T21: Not asked (survey skip: screener employment <20) | U21: No | V21: No | W21: 70 | X21: 0 | Y21: 0 | Z21: No | AB21: No | AC21: No | AD21: Yes | AE21: 1 | AF21: Moderate obstacle | AG21: Very severe obstacle | AH21: No obstacle | AI21: Major obstacle | AJ21: Electricity | AK21: Are taken directly from establishment records | AL21: =IF(H21="","",2024-H21) -> 24 | AM21: =IFERROR(IF(Z21="No",0,IF(Z21="Yes",AA21,"")),"") -> 0 | AN21: =IFERROR(IF(AD21="No",0,IF(AD21="Yes",AE21,"")),"") -> 1 | AO21: =IF(S21>0,"Yes","No") -> No | AP21: =IF(OR(K21="",L21="",L21<=0),"",K21/L21-1) -> 0.069444444 | AQ21: =IF(OR(K21="",L21="",L21<=0),"",(K21/L21)^(1/2)-1) -> 0.03413947 | AR21: =IF(OR(N21="",O21="",O21<=0),"",N21/O21-1) -> 0 | AS21: =IF(OR(K21="",N21="",N21<=0),"",K21/N21) -> 22000000 | AT21: =IF(OR(P21="",K21="",K21<=0),"",P21/K21) -> 0.14025974 | AU21: =IF(OR(Q21="",K21="",K21<=0),"",Q21/K21) -> 0.22727273 | AV21: =IF(OR(R21="",N21="",N21<=0),"",R21/N21) -> 42857143 | AW21: =IFERROR(IF(Z21="No",0,IF(Z21="Yes",AM21/K21,"")),"") -> 0 | AX21: =IF(OR(K21<Outlier_Audit!$H$2,K21>Outlier_Audit!$I$2),"Review","Normal") -> Normal | AY21: =IF(AL21="","Unknown",IF(AL21<10,"<10 years",IF(AL21<20,"10-19 years",IF(AL21<30,"20-29 years","30+ years")))) -> 20-29 years | AZ21: =IF(AQ21="","Missing",IF(AQ21>=EDA_Performance!$B$7,"High Growth",IF(AQ21<=EDA_Performance!$B$5,"Low Growth","Middle"))) -> Low Growth
A22: 1614163 | B22: Northern | C22: Small | D22: 30 | E22: 1040 | F22: 10 | G22: Manufacture of food products | H22: 1994 | I22: 4 | J22: 1 | K22: 2165000000 | L22: 1800000000 | M22: 100 | N22: 15 | O22: 10 | P22: 720000000 | Q22: 900000000 | R22: 10000000000 | S22: 0 | T22: Yes | U22: Yes | V22: No | W22: 0 | X22: 0 | Y22: 30 | Z22: Yes | AA22: 100000000 | AB22: No | AC22: No | AD22: Yes | AE22: 3 | AF22: Minor obstacle | AG22: No obstacle | AH22: No obstacle | AI22: Major obstacle | AJ22: Access to land | AK22: Are taken directly from establishment records | AL22: =IF(H22="","",2024-H22) -> 30 | AM22: =IFERROR(IF(Z22="No",0,IF(Z22="Yes",AA22,"")),"") -> 100000000 | AN22: =IFERROR(IF(AD22="No",0,IF(AD22="Yes",AE22,"")),"") -> 3 | AO22: =IF(S22>0,"Yes","No") -> No | AP22: =IF(OR(K22="",L22="",L22<=0),"",K22/L22-1) -> 0.20277778 | AQ22: =IF(OR(K22="",L22="",L22<=0),"",(K22/L22)^(1/2)-1) -> 0.096712258 | AR22: =IF(OR(N22="",O22="",O22<=0),"",N22/O22-1) -> 0.5 | AS22: =IF(OR(K22="",N22="",N22<=0),"",K22/N22) -> 1.4433333e+08 | AT22: =IF(OR(P22="",K22="",K22<=0),"",P22/K22) -> 0.33256351 | AU22: =IF(OR(Q22="",K22="",K22<=0),"",Q22/K22) -> 0.41570439 | AV22: =IF(OR(R22="",N22="",N22<=0),"",R22/N22) -> 6.6666667e+08 | AW22: =IFERROR(IF(Z22="No",0,IF(Z22="Yes",AM22/K22,"")),"") -> 0.046189376 | AX22: =IF(OR(K22<Outlier_Audit!$H$2,K22>Outlier_Audit!$I$2),"Review","Normal") -> Normal | AY22: =IF(AL22="","Unknown",IF(AL22<10,"<10 years",IF(AL22<20,"10-19 years",IF(AL22<30,"20-29 years","30+ years")))) -> 30+ years | AZ22: =IF(AQ22="","Missing",IF(AQ22>=EDA_Performance!$B$7,"High Growth",IF(AQ22<=EDA_Performance!$B$5,"Low Growth","Middle"))) -> Middle
A23: 1614165 | B23: Eastern | C23: Medium | D23: 13 | E23: 1061 | F23: 10 | G23: Manufacture of food products | H23: 2006 | I23: 22 | J23: 2.7846396 | K23: 600000000 | L23: 400000000 | M23: 90 | N23: 7 | O23: 8 | P23: 62400000 | Q23: 40000000 | R23: 90000000 | S23: 0 | T23: Not asked (survey skip: screener employment <20) | U23: Yes | V23: No | W23: 100 | X23: 0 | Y23: 0 | Z23: No | AB23: No | AC23: Yes | AD23: Yes | AE23: 3 | AF23: Major obstacle | AG23: Major obstacle | AH23: Minor obstacle | AI23: Moderate obstacle | AJ23: Practices of competitors in the informal sector | AK23: Are taken directly from establishment records | AL23: =IF(H23="","",2024-H23) -> 18 | AM23: =IFERROR(IF(Z23="No",0,IF(Z23="Yes",AA23,"")),"") -> 0 | AN23: =IFERROR(IF(AD23="No",0,IF(AD23="Yes",AE23,"")),"") -> 3 | AO23: =IF(S23>0,"Yes","No") -> No | AP23: =IF(OR(K23="",L23="",L23<=0),"",K23/L23-1) -> 0.5 | AQ23: =IF(OR(K23="",L23="",L23<=0),"",(K23/L23)^(1/2)-1) -> 0.22474487 | AR23: =IF(OR(N23="",O23="",O23<=0),"",N23/O23-1) -> -0.125 | AS23: =IF(OR(K23="",N23="",N23<=0),"",K23/N23) -> 85714286 | AT23: =IF(OR(P23="",K23="",K23<=0),"",P23/K23) -> 0.104 | AU23: =IF(OR(Q23="",K23="",K23<=0),"",Q23/K23) -> 0.066666667 | AV23: =IF(OR(R23="",N23="",N23<=0),"",R23/N23) -> 12857143 | AW23: =IFERROR(IF(Z23="No",0,IF(Z23="Yes",AM23/K23,"")),"") -> 0 | AX23: =IF(OR(K23<Outlier_Audit!$H$2,K23>Outlier_Audit!$I$2),"Review","Normal") -> Normal | AY23: =IF(AL23="","Unknown",IF(AL23<10,"<10 years",IF(AL23<20,"10-19 years",IF(AL23<30,"20-29 years","30+ years")))) -> 10-19 years | AZ23: =IF(AQ23="","Missing",IF(AQ23>=EDA_Performance!$B$7,"High Growth",IF(AQ23<=EDA_Performance!$B$5,"Low Growth","Middle"))) -> Middle
A24: 1614170 | B24: Central | C24: Small | D24: 15 | E24: 2511 | F24: 25 | G24: Manufacture of fabricated metal products | H24: 2009 | I24: 22 | J24: 316.31961 | K24: 800000000 | L24: 500000000 | M24: 90 | N24: 15 | O24: 7 | P24: 25000000 | S24: 20 | T24: Not asked (survey skip: screener employment <20) | U24: Yes | V24: No | W24: 60 | X24: 20 | Y24: 0 | Z24: No | AB24: Yes | AC24: No | AD24: Yes | AE24: 8 | AF24: Minor obstacle | AG24: No obstacle | AH24: No obstacle | AI24: No obstacle | AJ24: Corruption | AK24: Are in some case taken from books and in some case estimates | AL24: =IF(H24="","",2024-H24) -> 15 | AM24: =IFERROR(IF(Z24="No",0,IF(Z24="Yes",AA24,"")),"") -> 0 | AN24: =IFERROR(IF(AD24="No",0,IF(AD24="Yes",AE24,"")),"") -> 8 | AO24: =IF(S24>0,"Yes","No") -> Yes | AP24: =IF(OR(K24="",L24="",L24<=0),"",K24/L24-1) -> 0.6 | AQ24: =IF(OR(K24="",L24="",L24<=0),"",(K24/L24)^(1/2)-1) -> 0.26491106 | AR24: =IF(OR(N24="",O24="",O24<=0),"",N24/O24-1) -> 1.1428571 | AS24: =IF(OR(K24="",N24="",N24<=0),"",K24/N24) -> 53333333 | AT24: =IF(OR(P24="",K24="",K24<=0),"",P24/K24) -> 0.03125 | AU24: =IF(OR(Q24="",K24="",K24<=0),"",Q24/K24) | AV24: =IF(OR(R24="",N24="",N24<=0),"",R24/N24) | AW24: =IFERROR(IF(Z24="No",0,IF(Z24="Yes",AM24/K24,"")),"") -> 0 | AX24: =IF(OR(K24<Outlier_Audit!$H$2,K24>Outlier_Audit!$I$2),"Review","Normal") -> Normal | AY24: =IF(AL24="","Unknown",IF(AL24<10,"<10 years",IF(AL24<20,"10-19 years",IF(AL24<30,"20-29 years","30+ years")))) -> 10-19 years | AZ24: =IF(AQ24="","Missing",IF(AQ24>=EDA_Performance!$B$7,"High Growth",IF(AQ24<=EDA_Performance!$B$5,"Low Growth","Middle"))) -> Middle
A25: 1614171 | B25: Eastern | C25: Small | D25: 10 | E25: 2511 | F25: 25 | G25: Manufacture of fabricated metal products | H25: 2007 | I25: 20 | J25: 90.16523 | K25: 70000000 | L25: 10000000 | M25: 70 | N25: 10 | O25: 3 | P25: 10000000 | Q25: 30000000 | R25: 170000000 | S25: 0 | T25: Not asked (survey skip: screener employment <20) | U25: No | V25: No | W25: 90 | X25: 0 | Y25: 0 | Z25: No | AB25: No | AC25: No | AD25: Yes | AE25: 3 | AF25: Moderate obstacle | AG25: No obstacle | AH25: No obstacle | AI25: No obstacle | AJ25: Electricity | AK25: Are taken directly from establishment records | AL25: =IF(H25="","",2024-H25) -> 17 | AM25: =IFERROR(IF(Z25="No",0,IF(Z25="Yes",AA25,"")),"") -> 0 | AN25: =IFERROR(IF(AD25="No",0,IF(AD25="Yes",AE25,"")),"") -> 3 | AO25: =IF(S25>0,"Yes","No") -> No | AP25: =IF(OR(K25="",L25="",L25<=0),"",K25/L25-1) -> 6 | AQ25: =IF(OR(K25="",L25="",L25<=0),"",(K25/L25)^(1/2)-1) -> 1.6457513 | AR25: =IF(OR(N25="",O25="",O25<=0),"",N25/O25-1) -> 2.3333333 | AS25: =IF(OR(K25="",N25="",N25<=0),"",K25/N25) -> 7000000 | AT25: =IF(OR(P25="",K25="",K25<=0),"",P25/K25) -> 0.14285714 | AU25: =IF(OR(Q25="",K25="",K25<=0),"",Q25/K25) -> 0.42857143 | AV25: =IF(OR(R25="",N25="",N25<=0),"",R25/N25) -> 17000000 | AW25: =IFERROR(IF(Z25="No",0,IF(Z25="Yes",AM25/K25,"")),"") -> 0 | AX25: =IF(OR(K25<Outlier_Audit!$H$2,K25>Outlier_Audit!$I$2),"Review","Normal") -> Normal | AY25: =IF(AL25="","Unknown",IF(AL25<10,"<10 years",IF(AL25<20,"10-19 years",IF(AL25<30,"20-29 years","30+ years")))) -> 10-19 years | AZ25: =IF(AQ25="","Missing",IF(AQ25>=EDA_Performance!$B$7,"High Growth",IF(AQ25<=EDA_Performance!$B$5,"Low Growth","Middle"))) -> High Growth
A26: 1614174 | B26: Northern | C26: Small | D26: 6 | E26: 1811 | F26: 18 | G26: Printing and reproduction of recorded media | H26: 1997 | I26: 30 | J26: 18.668732 | K26: 15000000 | L26: 12000000 | M26: 100 | N26: 6 | O26: 6 | P26: 4000000 | Q26: 5000000 | R26: 100000000 | S26: 0 | T26: Not asked (survey skip: screener employment <20) | U26: No | V26: No | W26: 50 | X26: 50 | Y26: 0 | Z26: No | AB26: No | AC26: No | AD26: Yes | AE26: 5 | AF26: Major obstacle | AG26: Minor obstacle | AH26: Minor obstacle | AI26: Minor obstacle | AJ26: Business licensing and permits | AK26: Are in some case taken from books and in some case estimates | AL26: =IF(H26="","",2024-H26) -> 27 | AM26: =IFERROR(IF(Z26="No",0,IF(Z26="Yes",AA26,"")),"") -> 0 | AN26: =IFERROR(IF(AD26="No",0,IF(AD26="Yes",AE26,"")),"") -> 5 | AO26: =IF(S26>0,"Yes","No") -> No | AP26: =IF(OR(K26="",L26="",L26<=0),"",K26/L26-1) -> 0.25 | AQ26: =IF(OR(K26="",L26="",L26<=0),"",(K26/L26)^(1/2)-1) -> 0.11803399 | AR26: =IF(OR(N26="",O26="",O26<=0),"",N26/O26-1) -> 0 | AS26: =IF(OR(K26="",N26="",N26<=0),"",K26/N26) -> 2500000 | AT26: =IF(OR(P26="",K26="",K26<=0),"",P26/K26) -> 0.26666667 | AU26: =IF(OR(Q26="",K26="",K26<=0),"",Q26/K26) -> 0.33333333 | AV26: =IF(OR(R26="",N26="",N26<=0),"",R26/N26) -> 16666667 | AW26: =IFERROR(IF(Z26="No",0,IF(Z26="Yes",AM26/K26,"")),"") -> 0 | AX26: =IF(OR(K26<Outlier_Audit!$H$2,K26>Outlier_Audit!$I$2),"Review","Normal") -> Normal | AY26: =IF(AL26="","Unknown",IF(AL26<10,"<10 years",IF(AL26<20,"10-19 years",IF(AL26<30,"20-29 years","30+ years")))) -> 20-29 years | AZ26: =IF(AQ26="","Missing",IF(AQ26>=EDA_Performance!$B$7,"High Growth",IF(AQ26<=EDA_Performance!$B$5,"Low Growth","Middle"))) -> Middle
A27: 1614175 | B27: Northern | C27: Small | D27: 8 | E27: 1811 | F27: 18 | G27: Printing and reproduction of recorded media | H27: 2006 | I27: 19 | J27: 18.668732 | K27: 29430000 | L27: 22570000 | M27: 70 | N27: 4 | O27: 4 | P27: 8046000 | Q27: 17000000 | R27: 49570000 | S27: 0 | T27: Not asked (survey skip: screener employment <20) | U27: No | V27: No | W27: 60 | X27: 0 | Y27: 10 | Z27: Yes | AA27: 2460000 | AB27: No | AC27: No | AD27: Yes | AE27: 6 | AF27: Moderate obstacle | AG27: Minor obstacle | AH27: No obstacle | AI27: No obstacle | AJ27: Tax rates | AK27: Are estimates computed with some precision | AL27: =IF(H27="","",2024-H27) -> 18 | AM27: =IFERROR(IF(Z27="No",0,IF(Z27="Yes",AA27,"")),"") -> 2460000 | AN27: =IFERROR(IF(AD27="No",0,IF(AD27="Yes",AE27,"")),"") -> 6 | AO27: =IF(S27>0,"Yes","No") -> No | AP27: =IF(OR(K27="",L27="",L27<=0),"",K27/L27-1) -> 0.30394329 | AQ27: =IF(OR(K27="",L27="",L27<=0),"",(K27/L27)^(1/2)-1) -> 0.14190336 | AR27: =IF(OR(N27="",O27="",O27<=0),"",N27/O27-1) -> 0 | AS27: =IF(OR(K27="",N27="",N27<=0),"",K27/N27) -> 7357500 | AT27: =IF(OR(P27="",K27="",K27<=0),"",P27/K27) -> 0.2733945 | AU27: =IF(OR(Q27="",K27="",K27<=0),"",Q27/K27) -> 0.57764186 | AV27: =IF(OR(R27="",N27="",N27<=0),"",R27/N27) -> 12392500 | AW27: =IFERROR(IF(Z27="No",0,IF(Z27="Yes",AM27/K27,"")),"") -> 0.083588175 | AX27: =IF(OR(K27<Outlier_Audit!$H$2,K27>Outlier_Audit!$I$2),"Review","Normal") -> Normal | AY27: =IF(AL27="","Unknown",IF(AL27<10,"<10 years",IF(AL27<20,"10-19 years",IF(AL27<30,"20-29 years","30+ years")))) -> 10-19 years | AZ27: =IF(AQ27="","Missing",IF(AQ27>=EDA_Performance!$B$7,"High Growth",IF(AQ27<=EDA_Performance!$B$5,"Low Growth","Middle"))) -> Middle
